Workbook

Sheet Analisis quimico (Suelo)
A1: Numero | B1: Nº en cronosecuencia | C1: Nombre ubicacion | D1: Codigo | E1: Rep | F1: pH (mV) | G1: Conductivity (µS/cm) | H1: Temperatura (ºC) | I1: C Total (mg kg-1) | J1: N Total (mg kg-1) | K1: C:N ratio | L1: 13C | M1: 15N | N1: Fe Total (mg kg-1 dw soil) | O1: Fe2+ (mg kg-1 dw soil) | P1: Fe3+ (mg g-1 dw soil) | Q1: Fep (mg g-1 dw soil) | R1: Feo (mg g-1 dw soil) | S1: Fed (mg g-1 dw soil) | T1: Mn Oxidado (mg g-1 dw soil) | U1: Mnp (mg g-1 dw soil) | V1: Mno (mg g-1 dw soil) | W1: Mnd (mg g-1 dw soil) | X1: H2O2 (mg g-1 dw soil) | Y1: NH4 (mg kg-1 dw soil) | Z1: NO3- (mg kg-1 dw soil) | AA1: P olsen (mg kg-1 dw soil) | AB1: Ca2+ (cmol c kg-1) | AC1: Mg2+ (cmol c kg-1) | AD1: K+ (cmol c kg-1) | AE1: Na+ (cmol c kg-1) | AF1: CEC total (cmol c kg-1)
A2: 1 | B2: 1 | C2: Bellingshausen Dome | D2: BH1.1 | E2: 1 | F2: 7.762 | G2: 131.7 | H2: 20.5 | I2: 1810 | J2: 140 | K2: 12.929 | L2: -26.324 | M2: 0.903 | N2: 0.11402226 | O2: 2.549017 | P2: 0.11147324 | Q2: 2.45 | R2: 219.1 | S2: 205 | T2: 0.043855216 | U2: 0.45 | V2: 10.37 | W2: 9.34 | X2: 25.481241 | Y2: 10.100863 | Z2: 9.231462 | AA2: 102.22671 | AB2: 1.515 | AC2: 0.71 | AD2: 0.237 | AE2: 0.537 | AF2: 1.484
E3: 2 | F3: 7.803 | G3: 117.7 | H3: 19.9 | I3: 1800 | J3: 110 | K3: 16.364 | L3: -26.712 | M3: 0.912 | N3: 0.10332717 | O3: 2.5675024 | P3: 0.10075967 | Q3: 0.96 | R3: 226.7 | S3: 326.6 | T3: 0.027834251 | U3: 0.23 | V3: 9.75 | W3: 10.28 | X3: 27.511348 | Y3: 6.0490368 | Z3: 11.18274 | AA3: 102.19103 | AB3: 1.501 | AC3: 0.698 | AD3: 0.237 | AE3: 0.542 | AF3: 1.478
E4: 3 | F4: 7.88 | G4: 115.6 | H4: 19.8 | I4: 1800 | J4: 130 | K4: 13.846 | L4: -26.061 | M4: 0.906 | N4: 0.11869469 | O4: 2.1289256 | P4: 0.11656577 | Q4: 2.24 | R4: 196.4 | S4: 149.9 | T4: 0.040319774 | U4: 0.31 | V4: 9.73 | W4: 8.27 | X4: 26.09771 | Y4: 6.7857324 | Z4: 7.9449054 | AA4: 73.563981 | AB4: 1.227 | AC4: 0.586 | AD4: 0.208 | AE4: 0.435 | AF4: 1.229
E5: 4 | F5: 7.992 | G5: 117.6 | H5: 20.6 | I5: na | J5: na | N5: 0.1290301 | O5: 3.1234205 | P5: 0.12590668 | Q5: 2.58 | R5: 218.1 | S5: 283.8 | T5: 0.048392297 | U5: 0.27 | V5: 11.9 | W5: 8.13 | X5: 24.648902 | Y5: na | Z5: na | AA5: 99.996632 | AB5: 1.146 | AC5: 0.541 | AD5: 0.198 | AE5: 0.416 | AF5: 1.155
A6: 2 | B6: 2 | C6: Bellingshausen Dome | D6: BH1.2 | E6: 1 | F6: 7.694 | G6: 84.07 | H6: 21.4 | I6: 3000 | J6: 220 | K6: 13.636 | L6: -23.839 | M6: 0.954 | N6: 0.03872528 | O6: 1.1392405 | P6: 0.03758604 | Q6: 2.48 | R6: 206.9 | S6: 151.2 | T6: 0.04425497 | U6: 0.25 | V6: 6.23 | W6: 6.79 | X6: 12.980102 | Y6: 31.664746 | Z6: 0.54586145 | AA6: 58.24437 | AB6: 0.905 | AC6: 0.353 | AD6: 0.086 | AE6: 0.026 | AF6: 0.465
E7: 2 | F7: 7.788 | G7: 82.6 | H7: 20.8 | I7: 3410 | J7: 270 | K7: 12.63 | L7: -23.5 | M7: 0.903 | N7: 0.042152672 | O7: 1.00199 | P7: 0.041150682 | Q7: 2.66 | R7: 216.9 | S7: 129.5 | T7: 0.0886854 | U7: 0.16 | V7: 6.47 | W7: 11.79 | X7: 12.987085 | Y7: 33.897407 | Z7: 0.52265256 | AA7: 72.000304 | AB7: 0.928 | AC7: 0.377 | AD7: 0.091 | AE7: 0.135 | AF7: 0.603
E8: 3 | F8: 7.726 | G8: 80.58 | H8: 21 | I8: 3090 | J8: 330 | K8: 9.364 | L8: -23.012 | M8: 0.921 | N8: 0.053831515 | O8: 0.83304806 | P8: 0.052998466 | Q8: 1.6 | R8: 222.1 | S8: 100.9 | T8: 0.068845639 | U8: 0.31 | V8: 6.6 | W8: 10.41 | X8: 11.334895 | Y8: 47.054159 | Z8: 0.6619059 | AA8: 67.833494 | AB8: 0.863 | AC8: 0.346 | AD8: 0.076 | AE8: 0.105 | AF8: 0.527
E9: 4 | F9: 7.656 | G9: 80.72 | H9: 20.9 | I9: na | J9: na | N9: 0.054702123 | O9: 1.0479736 | P9: 0.05365415 | Q9: 1.48 | R9: 194.2 | S9: 151.8 | T9: 0.063560562 | U9: 0.22 | V9: 6.03 | W9: 7.43 | X9: 12.892268 | Y9: na | Z9: na | AA9: 77.204269 | AB9: 0.819 | AC9: 0.333 | AD9: 0.073 | AE9: 0.106 | AF9: 0.512
A10: 3 | B10: 3 | C10: Bellingshausen Dome | D10: BH1.3 | E10: 1 | F10: 7.325 | G10: 234.9 | H10: 21.2 | I10: 2180 | J10: 130 | K10: 16.769 | L10: -33.508 | M10: 0.404 | N10: 0.022259452 | O10: 0.78904899 | P10: 0.021470403 | Q10: 0.56 | R10: 268.7 | S10: 89.38 | T10: 0.068791743 | U10: 0.25 | V10: 8.02 | W10: 7.83 | X10: 15.162335 | Y10: 9.794294 | Z10: 0.84006273 | AA10: 30.919057 | AB10: 0.616 | AC10: 0.33 | AD10: 0.074 | AE10: 0.152 | AF10: 0.556
E11: 2 | F11: 7.359 | G11: 243.3 | H11: 20.8 | I11: 2110 | J11: 130 | K11: 16.231 | L11: -33.442 | M11: 0.4 | N11: 0.045891228 | O11: 0.90457792 | P11: 0.04498665 | Q11: 0.17 | R11: 250 | S11: 135.6 | T11: 0.051374992 | U11: 0.16 | V11: 7.09 | W11: 14.28 | X11: 16.611384 | Y11: 16.148041 | Z11: 0.58497973 | AA11: 31.590422 | AB11: 0.696 | AC11: 0.376 | AD11: 0.084 | AE11: 0.168 | AF11: 0.628
E12: 3 | F12: 7.351 | G12: 246.8 | H12: 21.1 | I12: 2310 | J12: 120 | K12: 19.25 | L12: -33.812 | M12: 0.421 | N12: 0.041081583 | O12: 0.9534846 | P12: 0.040128098 | Q12: 0.62 | R12: 251.9 | S12: 72.21 | T12: 0.046610124 | U12: 0.31 | V12: 7.66 | W12: 8.26 | X12: 15.313111 | Y12: 13.007683 | Z12: 0.86131965 | AA12: 33.023876 | AB12: 0.636 | AC12: 0.338 | AD12: 0.069 | AE12: 0.141 | AF12: 0.548
E13: 4 | F13: 7.298 | G13: 246.2 | H13: 20.7 | I13: na | J13: na | N13: 0.034149912 | O13: 0.65039062 | P13: 0.033499521 | Q13: 0.01 | R13: 239.2 | S13: 227.5 | T13: 0.038711017 | U13: 0.22 | V13: 7.68 | W13: 6.8 | X13: 18.791347 | Y13: na | Z13: na | AA13: 38.013747 | AB13: 0.721 | AC13: 0.388 | AD13: 0.082 | AE13: 0.166 | AF13: 0.637
A14: 4 | B14: 4 | C14: Bellingshausen Dome | D14: BH1.4 | E14: 1 | F14: 7.406 | G14: 84.64 | H14: 20.4 | I14: 2180 | J14: 150 | K14: 14.533 | L14: -28.864 | M14: 3.779 | N14: 0.056200252 | O14: 0.78646766 | P14: 0.055413784 | Q14: 0.84 | R14: 209.6 | S14: 198.4 | T14: 0.21090211 | U14: 0.18 | V14: 6.83 | W14: 5.06 | X14: 17.675361 | Y14: 12.352682 | Z14: 0.67857588 | AA14: 40.285204 | AB14: 0.874 | AC14: 0.5 | AD14: 0.081 | AE14: 0.128 | AF14: 0.709
E15: 2 | F15: 7.393 | G15: 83.38 | H15: 20.7 | I15: 2190 | J15: 160 | K15: 13.688 | L15: -28.021 | M15: 3.801 | N15: 0.036988178 | O15: 0.94125 | P15: 0.036046928 | Q15: 1.08 | R15: 203.5 | S15: 117.2 | T15: 0.20491886 | U15: 0.32 | V15: 6.95 | W15: 5.17 | X15: 17.183365 | Y15: 23.22491 | Z15: 0.51202208 | AA15: 44.216781 | AB15: 0.878 | AC15: 0.543 | AD15: 0.079 | AE15: 0.124 | AF15: 0.746
E16: 3 | F16: 7.385 | G16: 83.19 | H16: 20.6 | I16: 2100 | J16: 110 | K16: 19.091 | L16: -28.416 | M16: 3.519 | N16: 0.051605036 | O16: 0.63130602 | P16: 0.05097373 | Q16: 0.57 | R16: 185.6 | S16: 210.1 | T16: 0.20641609 | U16: 0.2 | V16: 6.41 | W16: 6.27 | X16: 17.778828 | Y16: 20.93602 | Z16: 0.55960888 | AA16: 44.737401 | AB16: 0.826 | AC16: 0.496 | AD16: 0.071 | AE16: 0.117 | AF16: 0.685
E17: 4 | F17: 7.319 | G17: 87.93 | H17: 20.5 | I17: na | J17: na | N17: 0.045960806 | O17: 0.99735886 | P17: 0.044963447 | Q17: 0.32 | R17: 192.4 | S17: 179.4 | T17: 0.20357053 | U17: 0.25 | V17: 6.67 | W17: 8 | X17: 16.894814 | Y17: na | Z17: na | AA17: 47.232786 | AB17: 0.864 | AC17: 0.524 | AD17: 0.071 | AE17: 0.118 | AF17: 0.713
A18: 5 | B18: 1 | C18: Bellingshausen Dome | D18: BH2.1 | E18: 1 | F18: 7.729 | G18: 111.6 | H18: 20.9 | I18: 4970 | J18: 370 | K18: 13.432 | L18: -25.866 | M18: 0.967 | N18: 0.0036864998 | O18: 1.1888779 | P18: 0.0024976219 | Q18: 3.5 | R18: 310.4 | S18: 314.1 | T18: 0.14357213 | U18: 0.18 | V18: 12.73 | W18: 11.6 | X18: 41.222224 | Y18: 6.252053 | Z18: 1.0842592 | AA18: 93.873706 | AB18: 1.04 | AC18: 1.283 | AD18: 0.096 | AE18: 0.137 | AF18: 1.515
E19: 2 | F19: 7.749 | G19: 109.5 | H19: 20.7 | I19: 4190 | J19: 320 | K19: 13.094 | L19: -25.841 | M19: 0.923 | N19: 0.0038061207 | O19: 1.0449216 | P19: 0.0027611991 | Q19: 3.49 | R19: 318.5 | S19: 250.1 | T19: 0.1561969 | U19: 0.25 | V19: 13.44 | W19: 10 | X19: 46.266074 | Y19: 7.6813448 | Z19: 2.2228305 | AA19: 91.014255 | AB19: 0.953 | AC19: 1.212 | AD19: 0.079 | AE19: 0.113 | AF19: 1.404
E20: 3 | F20: 7.784 | G20: 104.6 | H20: 20.7 | I20: 4910 | J20: 290 | K20: 16.931 | L20: -25.618 | M20: 0.966 | N20: 0.0047507513 | O20: 1.2996379 | P20: 0.0034511133 | Q20: 3.68 | R20: 345.6 | S20: 396.2 | T20: 0.16149246 | U20: 0.19 | V20: 14.8 | W20: 9.86 | X20: 49.115459 | Y20: 7.9822483 | Z20: 2.2666217 | AA20: 95.965988 | AB20: 1.04 | AC20: 1.334 | AD20: 0.078 | AE20: 0.117 | AF20: 1.529
E21: 4 | F21: 7.82 | G21: 109.3 | H21: 20.6 | I21: na | J21: na | N21: 0.0039580604 | O21: 1.4389747 | P21: 0.0025190857 | Q21: 2.97 | R21: 326.3 | S21: 277.9 | T21: 0.15441905 | U21: 0.27 | V21: 13.92 | W21: 9.59 | X21: 45.373146 | Y21: na | Z21: na | AA21: 95.408046 | AB21: 0.831 | AC21: 1.071 | AD21: 0.054 | AE21: 0.087 | AF21: 1.212
A22: 6 | B22: 2 | C22: Bellingshausen Dome | D22: BH2.2 | E22: 1 | F22: 8.058 | G22: 77.13 | H22: 22 | I22: 1530 | J22: 90 | K22: 17 | L22: -23.927 | M22: 2.004 | N22: 0.0039413151 | O22: 0.93012716 | P22: 0.0030111879 | Q22: 0.76 | R22: 322.4 | S22: 511.6 | T22: 0.12952736 | U22: 0.13 | V22: 11.85 | W22: 11.07 | X22: 17.806321 | Y22: 8.5728197 | Z22: 1.4754963 | AA22: 39.817164 | AB22: 0.568 | AC22: 0.493 | AD22: 0.015 | AE22: 0.047 | AF22: 0.554
E23: 2 | F23: 7.82 | G23: 78.21 | H23: 21.8 | I23: 1520 | J23: 80 | K23: 19 | L23: -23.302 | M23: 2.003 | N23: 0.0037913125 | O23: 0.59271845 | P23: 0.0031985941 | Q23: 1.08 | R23: 298.8 | S23: 326.4 | T23: 0.12099881 | U23: 0.32 | V23: 13.11 | W23: 11.95 | X23: 20.555725 | Y23: 8.2585391 | Z23: 1.2468063 | AA23: 38.684749 | AB23: 0.581 | AC23: 0.507 | AD23: 0.016 | AE23: 0.047 | AF23: 0.57
E24: 3 | F24: 8.024 | G24: 71.55 | H24: 22.6 | I24: 1430 | J24: 80 | K24: 17.875 | L24: -23.501 | M24: 2.011 | N24: 0.0030229048 | O24: 0.71497585 | P24: 0.0023079289 | Q24: 1.11 | R24: 300.2 | S24: 568.7 | T24: 0.12081576 | U24: 0.13 | V24: 12.96 | W24: 13.03 | X24: 19.556556 | Y24: 6.9228467 | Z24: 0.97237837 | AA24: 38.520366 | AB24: 0.634 | AC24: 0.553 | AD24: 0.02 | AE24: 0.053 | AF24: 0.626
E25: 4 | F25: 8.038 | G25: 67.89 | H25: 22.1 | I25: na | J25: na | N25: 0.003610088 | O25: 0.5735121 | P25: 0.0030365759 | Q25: 0.34 | R25: 310.6 | S25: 408.9 | T25: 0.10674023 | U25: 0.28 | V25: 13.2 | W25: 12.56 | X25: 27.465659 | Y25: na | Z25: na | AA25: 38.136807 | AB25: 0.676 | AC25: 0.458 | AD25: 0.012 | AE25: 0.044 | AF25: 0.514
A26: 7 | B26: 3 | C26: Bellingshausen Dome | D26: BH2.3 | E26: 1 | F26: 7.94 | G26: 61.68 | H26: 21.4 | I26: 950 | J26: 60 | K26: 15.833 | L26: -29.999 | M26: 7.438 | N26: 0.0031223484 | O26: 0.33703947 | P26: 0.002785309 | Q26: 0.61 | R26: 265.8 | S26: 300.3 | T26: 0.074476238 | U26: 0.45 | V26: 12.7 | W26: 9.55 | X26: 16.033308 | Y26: 6.8732411 | Z26: 1.8619247 | AA26: 19.551845 | AB26: 0.681 | AC26: 0.417 | AD26: 0.01 | AE26: 0.001 | AF26: 0.428
E27: 2 | F27: 7.942 | G27: 62.39 | H27: 21.8 | I27: 890 | J27: 40 | K27: 22.25 | L27: -29.351 | M27: 7.539 | N27: 0.0027878721 | O27: 0.38774704 | P27: 0.0024001251 | Q27: 0 | R27: 277.7 | S27: 375.1 | T27: 0.071934005 | U27: 0.12 | V27: 13.44 | W27: 13.42 | X27: 18.253047 | Y27: 7.1623048 | Z27: 1.8408907 | AA27: 20.115665 | AB27: 0.645 | AC27: 0.402 | AD27: 0.006 | AE27: 0.026 | AF27: 0.434
E28: 3 | F28: 7.998 | G28: 60.49 | H28: 22.1 | I28: 900 | J28: 70 | K28: 12.857 | L28: -29.601 | M28: 7.092 | N28: 0.0027552972 | O28: 0.28731466 | P28: 0.0024679825 | Q28: 0 | R28: 233.5 | S28: 114.5 | T28: 0.064405894 | U28: 0.12 | V28: 12.62 | W28: 10.09 | X28: 16.80603 | Y28: 6.7287092 | Z28: 1.6515841 | AA28: 29.027669 | AB28: 0.656 | AC28: 0.403 | AD28: 0.007 | AE28: 0.028 | AF28: 0.437
E29: 4 | F29: 8.003 | G29: 63.76 | H29: 22.1 | I29: na | J29: na | N29: 0.0025250945 | O29: 0.36562604 | P29: 0.0021594685 | Q29: 0 | R29: 233.8 | S29: 345.3 | T29: 0.056518011 | U29: 0.11 | V29: 13.69 | W29: 12.67 | X29: 22.345597 | Y29: na | Z29: na | AA29: 25.590182 | AB29: 0.609 | AC29: 0.366 | AD29: 0.002 | AE29: 0.025 | AF29: 0.393
A30: 8 | B30: 4 | C30: Bellingshausen Dome | D30: BH2.4 | E30: 1 | F30: 7.48 | G30: 52.94 | H30: 21.3 | I30: 5420 | J30: 430 | K30: 12.605 | L30: -27.368 | M30: -0.763 | N30: 0.0059444409 | O30: 1.2230159 | P30: 0.004721425 | Q30: 3.96 | R30: 265.5 | S30: 221.9 | T30: 0.020181552 | U30: 0.19 | V30: 6.7 | W30: 11.04 | X30: 21.160357 | Y30: 7.908151 | Z30: 3.6217601 | AA30: 58.091582 | AB30: 0.983 | AC30: 0.681 | AD30: 0.063 | AE30: 0.174 | AF30: 0.918
E31: 2 | F31: 7.467 | G31: 51.71 | H31: 21.6 | I31: 5820 | J31: 330 | K31: 17.636 | L31: -27.501 | M31: -0.681 | N31: 0.005137459 | O31: 0.89423394 | P31: 0.004243225 | Q31: 1.18 | R31: 260.2 | S31: 270.7 | T31: 0.011548596 | U31: 0.09 | V31: 7 | W31: 5.94 | X31: 21.437887 | Y31: 7.118208 | Z31: 3.2078959 | AA31: 58.826465 | AB31: 0.95 | AC31: 0.663 | AD31: 0.062 | AE31: 0.169 | AF31: 0.894
E32: 3 | F32: 7.413 | G32: 52.6 | H32: 21.7 | I32: 5770 | J32: 290 | K32: 19.897 | L32: -27.082 | M32: -0.783 | N32: 0.006448663 | O32: 0.80927327 | P32: 0.0056393897 | Q32: 3.62 | R32: 247 | S32: 261 | T32: 0.015225747 | U32: 0.31 | V32: 7.05 | W32: 7.05 | X32: 22.268467 | Y32: 7.1972023 | Z32: 2.0812656 | AA32: 58.593453 | AB32: 0.831 | AC32: 0.545 | AD32: 0.054 | AE32: 0.144 | AF32: 0.744
E33: 4 | F33: 7.439 | G33: 52.09 | H33: 21.7 | I33: na | J33: na | N33: 0.0066788857 | O33: 0.80767968 | P33: 0.005871206 | Q33: 3.51 | R33: 235.6 | S33: 177.1 | T33: 0.018811296 | U33: 0.11 | V33: 6.76 | W33: 5.19 | X33: 21.364527 | Y33: na | Z33: na | AA33: 61.120733 | AB33: 0.848 | AC33: 0.55 | AD33: 0.069 | AE33: 0.167 | AF33: 0.786
A34: 9 | B34: 1 | C34: Marian Cove | D34: MC.1.1 | E34: 1 | F34: 7.725 | G34: 79.96 | H34: 22 | I34: 2220 | J34: 130 | K34: 17.077 | L34: -26.243 | M34: 3.506 | N34: 0.010435142 | O34: 0.10140294 | P34: 0.010333739 | Q34: 15.87 | R34: 520.3 | S34: 674.2 | T34: 3.5162144 | U34: 0.22 | V34: 1.15 | W34: 0.54 | X34: 26.96647 | Y34: 4.6403825 | Z34: 0.60083718 | AA34: 5.7043749 | AB34: 0.1 | AC34: 0.065 | AD34: 0 | AE34: 0.012 | AF34: 0.077
E35: 2 | F35: 7.668 | G35: 77.99 | H35: 21.5 | I35: 2310 | J35: 170 | K35: 13.588 | L35: -27.092 | M35: 3.671 | N35: 0.010643845 | O35: 0.10216963 | P35: 0.010541675 | Q35: 15.84 | R35: 474.1 | S35: 781 | T35: 3.6763226 | U35: 0.25 | V35: 0.94 | W35: 0.51 | X35: 33.401044 | Y35: 4.8575259 | Z35: 0.64297237 | AA35: 5.3935596 | AB35: 0.091 | AC35: 0.06 | AD35: 0 | AE35: 0.011 | AF35: 0.071
E36: 3 | F36: 7.724 | G36: 82.71 | H36: 21.4 | I36: 2530 | J36: 120 | K36: 21.083 | L36: -26.822 | M36: 3.61 | N36: 0.012045608 | O36: 0.051084813 | P36: 0.011994523 | Q36: 17.44 | R36: 484.5 | S36: 972 | T36: 3.9225876 | U36: 0.08 | V36: 1 | W36: 1.01 | X36: 36.853087 | Y36: 5.2194315 | Z36: 0.72724273 | AA36: 6.5454045 | AB36: 0.07 | AC36: 0.047 | AD36: 0 | AE36: 0.009 | AF36: 0.056
E37: 4 | F37: 7.713 | G37: 85.27 | H37: 21.5 | I37: na | J37: na | N37: 0.013729177 | O37: 0.077493351 | P37: 0.013651684 | Q37: 15.22 | R37: 464.3 | S37: 1169 | T37: 3.6419484 | U37: 0.15 | V37: 0.98 | W37: 0.77 | X37: 37.110016 | Y37: na | Z37: na | AA37: 7.4595671 | AB37: 0.094 | AC37: 0.06 | AD37: 0 | AE37: 0.011 | AF37: 0.071
A38: 10 | B38: 2 | C38: Marian Cove | D38: MC.1.2 | E38: 1 | F38: 7.422 | G38: 47.26 | H38: 21.3 | I38: 3720 | J38: 280 | K38: 13.286 | L38: -27.752 | M38: -2.268 | N38: 0.0087211814 | O38: 0.025256538 | P38: 0.0086959249 | Q38: 11.58 | R38: 762.4 | S38: 563.9 | T38: 0.59565666 | U38: 0.35 | V38: 5.44 | W38: 0.26 | X38: 15.316988 | Y38: 7.1749113 | Z38: 0.61969452 | AA38: 14.126354 | AB38: 0.159 | AC38: 0.104 | AD38: 0.015 | AE38: 0.036 | AF38: 0.155
E39: 2 | F39: 7.426 | G39: 47.97 | H39: 21.6 | I39: 4910 | J39: 330 | K39: 14.879 | L39: -28.022 | M39: -2.112 | N39: 0.010120432 | O39: 0.02497545 | P39: 0.010095456 | Q39: 11.65 | R39: 777.8 | S39: 601.5 | T39: 0.66201193 | U39: 0.41 | V39: 5.7 | W39: 3 | X39: 13.824402 | Y39: 6.5776888 | Z39: 0.64142332 | AA39: 14.838753 | AB39: 0.143 | AC39: 0.093 | AD39: 0.01 | AE39: 0.032 | AF39: 0.136
E40: 3 | F40: 7.31 | G40: 48.86 | H40: 21.8 | I40: 3010 | J40: 260 | K40: 11.577 | L40: -27.534 | M40: -2.304 | N40: 0.0094314138 | O40: 0.049934555 | P40: 0.0093814792 | Q40: 7.79 | R40: 1031 | S40: 532.6 | T40: 0.71728751 | U40: 0.53 | V40: 7.27 | W40: 2.9 | X40: 14.515035 | Y40: 12.773872 | Z40: 1.9451513 | AA40: 15.916039 | AB40: 0.16 | AC40: 0.102 | AD40: 0.014 | AE40: 0.036 | AF40: 0.152
...

Sheet FTIR Antartico (Suelo)
A1: Wavenumber | B1: bell 1.1.1 | C1: bell 1.1.2 | D1: bell 1.1.3 | E1: bell 1.1.4 | F1: bell 1.2.1 | G1: bell 1.2.2 | H1: bell 1.2.3 | I1: bell 1.2.4 | J1: bell 1.3.1 | K1: bell 1.3.2 | L1: bell 1.3.3 | M1: bell 1.3.4 | N1: bell 1.4.1 | O1: bell 1.4.2 | P1: bell 1.4.3 | Q1: bell 1.4.4 | R1: bell 2.1.1 | S1: bell 2.1.2 | T1: bell 2.1.3 | U1: bell 2.1.4 | V1: bell 2.2.2 | W1: bell 2.2.3 | X1: bell 2.2.4 | Y1: bell 2.3.1 | Z1: bell 2.3.2 | AA1: bell 2.3.3 | AB1: bell 2.3.4 | AC1: bell 2.4.1 | AD1: bell 2.4.2 | AE1: bell 2.4.3 | AF1: bell 2.4.4 | AG1: BP 1.1.1 | AH1: BP 1.1.2 | AI1: BP 1.1.3 | AJ1: BP 1.1.4 | AK1: BP 1.2.1 | AL1: BP 1.2.2 | AM1: BP 1.2.3 | AN1: BP 1.2.4 | AO1: BP 1.3.1 | AP1: BP 1.3.2 | AQ1: BP 1.3.3 | AR1: BP 1.3.4 | AS1: BP 1.4.1 | AT1: BP 1.4.2 | AU1: BP 1.4.3 | AV1: BP 1.4.4 | AW1: BP 2.1.1 | AX1: BP 2.1.2 | AY1: BP 2.1.3 | AZ1: BP 2.1.4 | BA1: BP 2.2.1 | BB1: BP 2.2.2 | BC1: BP 2.2.3 | BD1: BP 2.2.4 | BE1: BP 2.3.1 | BF1: BP 2.3.2 | BG1: BP 2.3.3 | BH1: BP 2.3.4 | BI1: BP 2.4.1 | BJ1: BP 2.4.2 | BK1: BP 2.4.3 | BL1: BP 2.4.4 | BM1: BP 3.1.1 | BN1: BP 3.1.2 | BO1: BP 3.1.3 | BP1: BP 3.1.4 | BQ1: BP 3.2.1 | BR1: BP 3.2.2 | BS1: BP 3.2.3 | BT1: BP 3.2.4 | BU1: BP 3.3.1 | BV1: BP 3.3.2 | BW1: BP 3.3.3 | BX1: BP 3.3.4 | BY1: BP 3.4.1 | BZ1: BP 3.4.2 | CA1: BP 3.4.3 | CB1: BP 3.4.4 | CC1: MC 1.1.1 | CD1: MC 1.1.2 | CE1: MC 1.1.3 | CF1: MC 1.1.4 | CG1: MC 1.2.1 | CH1: MC 1.2.2 | CI1: MC 1.2.3 | CJ1: MC 1.2.4 | CK1: MC 1.3.1 | CL1: MC 1.3.2 | CM1: MC 1.3.3 | CN1: MC 1.3.4 | CO1: MC 1.4.1 | CP1: MC 1.4.2 | CQ1: MC 1.4.3 | CR1: MC 1.4.4 | CS1: NG 1.1.1 | CT1: NG 1.1.2 | CU1: NG 1.1.3 | CV1: NG 1.1.4 | CW1: NG 1.2.1 | CX1: NG 1.2.2 | CY1: NG 1.2.3 | CZ1: NG 1.2.4 | DA1: NG 1.3.1 | DB1: NG 1.3.2 | DC1: NG 1.3.3 | DD1: NG 1.3.4 | DE1: NG 1.4.1 | DF1: NG 1.4.2 | DG1: NG 1.4.3 | DH1: NG 1.4.4 | DI1: PP 1.1.1 | DJ1: PP 1.1.2 | DK1: PP 1.1.3 | DL1: PP 1.1.4 | DM1: PP 1.2.1 | DN1: PP 1.2.2 | DO1: PP 1.2.3 | DP1: PP 1.2.4 | DQ1: PP 1.3.1 | DR1: PP 1.3.2 | DS1: PP 1.3.3 | DT1: PP 1.3.4 | DU1: PP 1.4.1 | DV1: PP 1.4.2 | DW1: PP 1.4.3 | DX1: PP 1.4.4
A2: 600.248 | B2: 65.112 | C2: 66.6591 | D2: 56.7045 | E2: 76.598 | F2: 74.4331 | G2: 83.7385 | H2: 89.1594 | I2: 90.8304 | J2: 93.5659 | K2: 81.2383 | L2: 70.9905 | M2: 57.209 | N2: 66.2248 | O2: 87.8655 | P2: 83.4295 | Q2: 86.4312 | R2: 74.7739 | S2: 66.3665 | T2: 56.5011 | U2: 66.8794 | V2: 57.6962 | W2: 75.7591 | X2: 87.2216 | Y2: 88.5866 | Z2: 80.7547 | AA2: 85.4796 | AB2: 85.6192 | AC2: 81.1795 | AD2: 80.4272 | AE2: 89.7084 | AF2: 88.8594 | AG2: 67.054 | AH2: 65.6421 | AI2: 62.2713 | AJ2: 62.7569 | AK2: 73.8278 | AL2: 62.2612 | AM2: 52.3102 | AN2: 58.6488 | AO2: 69.913 | AP2: 68.0323 | AQ2: 63.6798 | AR2: 65.9712 | AS2: 84.6796 | AT2: 87.8235 | AU2: 89.9704 | AV2: 88.3712 | AW2: 91.6108 | AX2: 92.6222 | AY2: 94.3769 | AZ2: 89.8762 | BA2: 89.659 | BB2: 85.3282 | BC2: 88.8046 | BD2: 90.5254 | BE2: 93.5346 | BF2: 91.5992 | BG2: 90.0604 | BH2: 88.1898 | BI2: 101.632 | BJ2: 100.877 | BK2: 101.496 | BL2: 99.8515 | BM2: 93.3577 | BN2: 93.0177 | BO2: 98.0041 | BP2: 97.3134 | BQ2: 99.2503 | BR2: 88.6483 | BS2: 80.2995 | BT2: 95.1307 | BU2: 86.8057 | BV2: 86.7369 | BW2: 81.3509 | BX2: 96.0909 | BY2: 84.9097 | BZ2: 86.3866 | CA2: 83.9842 | CB2: 84.1392 | CC2: 82.0356 | CD2: 79.6883 | CE2: 77.2113 | CF2: 83.7453 | CG2: 79.7523 | CH2: 84.7099 | CI2: 85.599 | CJ2: 77.289 | CK2: 87.0839 | CL2: 81.0423 | CM2: 81.002 | CN2: 82.2274 | CO2: 89.0764 | CP2: 85.5941 | CQ2: 82.1132 | CR2: 82.5868 | CS2: 73.0078 | CT2: 69.391 | CU2: 70.5408 | CV2: 71.3092 | CW2: 74.7217 | CX2: 74.6094 | CY2: 76.5566 | CZ2: 76.5905 | DA2: 75.1926 | DB2: 78.5744 | DC2: 78.7129 | DD2: 78.7129 | DE2: 75.5541 | DF2: 79.1186 | DG2: 83.7957 | DH2: 77.1951 | DI2: 88.7121 | DJ2: 88.7121 | DK2: 80.4227 | DL2: 88.0145 | DM2: 82.7075 | DN2: 85.6278 | DO2: 90.8541 | DP2: 80.5877 | DQ2: 86.7281 | DR2: 81.6313 | DS2: 80.2523 | DT2: 84.8551 | DU2: 81.0626 | DV2: 78.1732 | DW2: 78.1732 | DX2: 80.8059
A3: 602.112 | B3: 63.9449 | C3: 68.2907 | D3: 60.7686 | E3: 78.4932 | F3: 78.2911 | G3: 82.7078 | H3: 93.1215 | I3: 88.3885 | J3: 97.3869 | K3: 84.8121 | L3: 70.9929 | M3: 62.8464 | N3: 69.959 | O3: 87.4991 | P3: 85.3564 | Q3: 85.7793 | R3: 71.6838 | S3: 67.3963 | T3: 59.8729 | U3: 69.639 | V3: 59.6966 | W3: 79.7027 | X3: 82.6404 | Y3: 85.7571 | Z3: 78.7004 | AA3: 86.916 | AB3: 85.5084 | AC3: 81.3707 | AD3: 82.8628 | AE3: 92.8737 | AF3: 87.6674 | AG3: 68.944 | AH3: 70.8564 | AI3: 64.2859 | AJ3: 62.0175 | AK3: 72.5897 | AL3: 62.5292 | AM3: 54.9831 | AN3: 61.073 | AO3: 71.6112 | AP3: 67.3355 | AQ3: 67.279 | AR3: 65.1249 | AS3: 85.0121 | AT3: 87.8809 | AU3: 90.1277 | AV3: 88.3189 | AW3: 92.1052 | AX3: 92.6625 | AY3: 94.4923 | AZ3: 90.216 | BA3: 90.2739 | BB3: 85.8936 | BC3: 89.3535 | BD3: 90.8566 | BE3: 93.7186 | BF3: 92.1966 | BG3: 90.0872 | BH3: 88.9321 | BI3: 101.916 | BJ3: 101.543 | BK3: 101.898 | BL3: 100.52 | BM3: 94.0782 | BN3: 93.11 | BO3: 97.6257 | BP3: 97.3665 | BQ3: 99.9362 | BR3: 89.2071 | BS3: 81.0063 | BT3: 95.9891 | BU3: 86.7272 | BV3: 86.4467 | BW3: 81.6706 | BX3: 95.5306 | BY3: 84.3749 | BZ3: 87.32 | CA3: 84.674 | CB3: 84.336 | CC3: 82.4868 | CD3: 79.876 | CE3: 77.939 | CF3: 83.6288 | CG3: 79.7016 | CH3: 85.1977 | CI3: 85.2455 | CJ3: 77.5605 | CK3: 87.6835 | CL3: 81.6108 | CM3: 81.8897 | CN3: 82.7996 | CO3: 90.0016 | CP3: 85.6862 | CQ3: 82.7474 | CR3: 83.0882 | CS3: 73.3513 | CT3: 70.1655 | CU3: 70.8838 | CV3: 70.9916 | CW3: 74.3193 | CX3: 74.8968 | CY3: 76.7604 | CZ3: 76.3932 | DA3: 75.2062 | DB3: 78.1909 | DC3: 78.8723 | DD3: 78.8723 | DE3: 75.3642 | DF3: 79.2861 | DG3: 83.7757 | DH3: 77.3865 | DI3: 89.1427 | DJ3: 89.1427 | DK3: 80.9205 | DL3: 88.6587 | DM3: 83.2189 | DN3: 85.2867 | DO3: 91.4301 | DP3: 81.1214 | DQ3: 87.4832 | DR3: 83.0712 | DS3: 81.0146 | DT3: 85.2039 | DU3: 82.6099 | DV3: 78.3393 | DW3: 78.3393 | DX3: 81.808
A4: 603.976 | B4: 64.3103 | C4: 72.6914 | D4: 66.5813 | E4: 76.7376 | F4: 81.0083 | G4: 82.2272 | H4: 89.2113 | I4: 88.9772 | J4: 95.7007 | K4: 77.9566 | L4: 72.3881 | M4: 64.7615 | N4: 69.6362 | O4: 90.5233 | P4: 85.235 | Q4: 84.3894 | R4: 61.7983 | S4: 65.0855 | T4: 60.5081 | U4: 71.413 | V4: 63.3504 | W4: 82.3579 | X4: 78.7594 | Y4: 83.754 | Z4: 83.0322 | AA4: 87.8899 | AB4: 86.5366 | AC4: 78.8222 | AD4: 86.0927 | AE4: 92.0025 | AF4: 88.2933 | AG4: 71.6116 | AH4: 70.358 | AI4: 65.5689 | AJ4: 61.427 | AK4: 70.8184 | AL4: 65.6289 | AM4: 57.5452 | AN4: 62.4827 | AO4: 70.9833 | AP4: 68.6626 | AQ4: 68.3388 | AR4: 64.563 | AS4: 85.4051 | AT4: 87.6476 | AU4: 89.7336 | AV4: 88.5325 | AW4: 91.7893 | AX4: 93.0386 | AY4: 95.1239 | AZ4: 90.356 | BA4: 90.2991 | BB4: 86.5183 | BC4: 89.9752 | BD4: 91.3412 | BE4: 94.5684 | BF4: 93.2745 | BG4: 90.8729 | BH4: 89.8499 | BI4: 101.541 | BJ4: 101.592 | BK4: 102.038 | BL4: 100.379 | BM4: 94.5059 | BN4: 92.7643 | BO4: 97.2887 | BP4: 97.4654 | BQ4: 100.088 | BR4: 89.5307 | BS4: 81.8413 | BT4: 95.9331 | BU4: 86.8832 | BV4: 86.2163 | BW4: 81.9284 | BX4: 95.4039 | BY4: 83.116 | BZ4: 88.0839 | CA4: 85.1471 | CB4: 84.0985 | CC4: 83.101 | CD4: 80.4511 | CE4: 78.7721 | CF4: 84.2394 | CG4: 79.9979 | CH4: 85.5857 | CI4: 84.7365 | CJ4: 77.8382 | CK4: 88.0029 | CL4: 82.3672 | CM4: 82.5252 | CN4: 84.1105 | CO4: 90.2781 | CP4: 86.5288 | CQ4: 82.7695 | CR4: 83.923 | CS4: 74.1772 | CT4: 69.9114 | CU4: 71.0983 | CV4: 71.5528 | CW4: 74.5419 | CX4: 74.4986 | CY4: 76.8417 | CZ4: 76.4267 | DA4: 75.5354 | DB4: 78.1091 | DC4: 78.6916 | DD4: 78.6916 | DE4: 74.7787 | DF4: 79.0331 | DG4: 84.0375 | DH4: 77.2933 | DI4: 89.5383 | DJ4: 89.5383 | DK4: 81.2222 | DL4: 89.246 | DM4: 83.8841 | DN4: 85.5144 | DO4: 92.0881 | DP4: 81.6417 | DQ4: 88.4108 | DR4: 84.2272 | DS4: 82.1849 | DT4: 86.4853 | DU4: 83.7216 | DV4: 79.5672 | DW4: 79.5672 | DX4: 82.8051
A5: 605.84 | B5: 66.2635 | C5: 73.8737 | D5: 71.4413 | E5: 77.7525 | F5: 81.211 | G5: 83.2896 | H5: 90.0792 | I5: 91.9132 | J5: 93.0486 | K5: 77.0376 | L5: 72.5961 | M5: 66.8513 | N5: 68.9572 | O5: 90.5976 | P5: 83.1694 | Q5: 83.1429 | R5: 50.8152 | S5: 61.6631 | T5: 60.2228 | U5: 68.6279 | V5: 65.7588 | W5: 81.6556 | X5: 76.0055 | Y5: 86.652 | Z5: 84.3409 | AA5: 87.846 | AB5: 88.9593 | AC5: 80.1047 | AD5: 85.3856 | AE5: 90.8124 | AF5: 88.8953 | AG5: 74.0497 | AH5: 65.2201 | AI5: 63.9025 | AJ5: 63.277 | AK5: 72.8574 | AL5: 66.4171 | AM5: 59.4568 | AN5: 59.8963 | AO5: 70.2852 | AP5: 70.4715 | AQ5: 69.3046 | AR5: 66.5567 | AS5: 85.4383 | AT5: 87.795 | AU5: 89.6261 | AV5: 88.8022 | AW5: 91.9223 | AX5: 93.5154 | AY5: 95.9326 | AZ5: 90.6219 | BA5: 90.928 | BB5: 87.1073 | BC5: 90.1842 | BD5: 91.8192 | BE5: 94.4272 | BF5: 93.6238 | BG5: 91.7507 | BH5: 89.5591 | BI5: 102.061 | BJ5: 102.216 | BK5: 102.334 | BL5: 100.699 | BM5: 94.6396 | BN5: 92.5146 | BO5: 97.3549 | BP5: 97.3446 | BQ5: 99.5118 | BR5: 89.2952 | BS5: 81.6573 | BT5: 95.4911 | BU5: 86.999 | BV5: 86.1869 | BW5: 81.8503 | BX5: 95.6145 | BY5: 83.2066 | BZ5: 88.2173 | CA5: 85.3911 | CB5: 84.0607 | CC5: 83.554 | CD5: 80.9497 | CE5: 78.8491 | CF5: 84.6811 | CG5: 80.8333 | CH5: 85.3348 | CI5: 84.837 | CJ5: 78.1264 | CK5: 88.6988 | CL5: 82.5453 | CM5: 82.7581 | CN5: 84.9819 | CO5: 90.4849 | CP5: 86.8331 | CQ5: 82.9586 | CR5: 83.7058 | CS5: 74.355 | CT5: 69.7594 | CU5: 71.428 | CV5: 71.1675 | CW5: 74.9041 | CX5: 74.558 | CY5: 77.185 | CZ5: 77.0173 | DA5: 75.7041 | DB5: 78.9007 | DC5: 78.7184 | DD5: 78.7184 | DE5: 75.1369 | DF5: 79.0405 | DG5: 83.9814 | DH5: 77.2437 | DI5: 90.2006 | DJ5: 90.2006 | DK5: 81.927 | DL5: 90.168 | DM5: 84.5844 | DN5: 86.0514 | DO5: 92.2463 | DP5: 82.3494 | DQ5: 89.2258 | DR5: 85.1575 | DS5: 83.1189 | DT5: 86.9003 | DU5: 84.0886 | DV5: 80.988 | DW5: 80.988 | DX5: 84.0584
A6: 607.704 | B6: 65.9544 | C6: 73.5734 | D6: 71.9191 | E6: 79.4194 | F6: 77.7541 | G6: 83.8426 | H6: 87.7524 | I6: 92.7961 | J6: 93.0068 | K6: 83.5585 | L6: 73.1256 | M6: 66.0078 | N6: 69.2534 | O6: 88.6709 | P6: 84.4042 | Q6: 85.728 | R6: 42.287 | S6: 61.196 | T6: 59.5965 | U6: 69.4153 | V6: 65.7963 | W6: 78.0152 | X6: 76.0451 | Y6: 88.1048 | Z6: 82.515 | AA6: 87.3061 | AB6: 88.0154 | AC6: 84.2554 | AD6: 84.0704 | AE6: 91.0406 | AF6: 87.0069 | AG6: 72.2493 | AH6: 65.3023 | AI6: 61.9846 | AJ6: 63.8388 | AK6: 72.3461 | AL6: 64.0685 | AM6: 59.8983 | AN6: 58.8942 | AO6: 72.6878 | AP6: 72.7875 | AQ6: 68.9006 | AR6: 67.1355 | AS6: 85.5538 | AT6: 88.2736 | AU6: 89.5314 | AV6: 89.1764 | AW6: 92.6689 | AX6: 94.0309 | AY6: 96.5784 | AZ6: 91.1747 | BA6: 91.5482 | BB6: 87.8854 | BC6: 90.3367 | BD6: 92.0467 | BE6: 94.4609 | BF6: 93.5272 | BG6: 91.6816 | BH6: 89.5138 | BI6: 102.402 | BJ6: 103.005 | BK6: 102.358 | BL6: 100.863 | BM6: 94.7366 | BN6: 92.4543 | BO6: 97.9989 | BP6: 97.4813 | BQ6: 99.486 | BR6: 89.1605 | BS6: 81.0582 | BT6: 95.4555 | BU6: 86.826 | BV6: 85.8748 | BW6: 81.9826 | BX6: 95.3361 | BY6: 84.1709 | BZ6: 87.8608 | CA6: 85.6021 | CB6: 84.3341 | CC6: 83.7342 | CD6: 81.5105 | CE6: 79.4452 | CF6: 84.7877 | CG6: 81.2544 | CH6: 85.583 | CI6: 84.9724 | CJ6: 78.6186 | CK6: 89.2637 | CL6: 82.7178 | CM6: 83.347 | CN6: 85.1681 | CO6: 91.0296 | CP6: 86.9204 | CQ6: 83.2403 | CR6: 83.8067 | CS6: 73.9596 | CT6: 69.6589 | CU6: 72.0556 | CV6: 72.0362 | CW6: 75.0723 | CX6: 75.3001 | CY6: 77.4596 | CZ6: 76.7377 | DA6: 75.4467 | DB6: 79.428 | DC6: 78.9189 | DD6: 78.9189 | DE6: 75.6203 | DF6: 78.8451 | DG6: 83.7188 | DH6: 77.2569 | DI6: 90.5701 | DJ6: 90.5701 | DK6: 82.6678 | DL6: 90.818 | DM6: 85.1301 | DN6: 86.8487 | DO6: 92.441 | DP6: 83.2102 | DQ6: 90.0459 | DR6: 85.1192 | DS6: 83.8838 | DT6: 87.2824 | DU6: 84.5381 | DV6: 81.4038 | DW6: 81.4038 | DX6: 84.6516
A7: 609.569 | B7: 65.5102 | C7: 75.2223 | D7: 71.5429 | E7: 78.3738 | F7: 77.3192 | G7: 83.1892 | H7: 90.2106 | I7: 93.0042 | J7: 94.4902 | K7: 80.7187 | L7: 72.0606 | M7: 65.4741 | N7: 70.5243 | O7: 90.3903 | P7: 85.2857 | Q7: 89.9385 | R7: 42.4709 | S7: 63.0335 | T7: 60.8383 | U7: 69.4345 | V7: 65.8252 | W7: 77.3546 | X7: 76.8251 | Y7: 88.5063 | Z7: 85.0399 | AA7: 85.4434 | AB7: 85.0097 | AC7: 84.6285 | AD7: 84.9121 | AE7: 91.5531 | AF7: 87.3642 | AG7: 71.7286 | AH7: 67.1437 | AI7: 62.6509 | AJ7: 65.4086 | AK7: 73.7626 | AL7: 64.4642 | AM7: 62.8543 | AN7: 61.1703 | AO7: 75.5887 | AP7: 74.0912 | AQ7: 69.9862 | AR7: 66.4611 | AS7: 85.7825 | AT7: 88.0543 | AU7: 89.7215 | AV7: 89.3722 | AW7: 92.9069 | AX7: 94.2419 | AY7: 96.6411 | AZ7: 92.0251 | BA7: 91.8675 | BB7: 88.5585 | BC7: 91.0429 | BD7: 92.4064 | BE7: 95.1732 | BF7: 94.3368 | BG7: 91.7814 | BH7: 90.045 | BI7: 102.501 | BJ7: 102.792 | BK7: 102.469 | BL7: 100.537 | BM7: 94.8143 | BN7: 92.7064 | BO7: 98.9876 | BP7: 97.4233 | BQ7: 99.5582 | BR7: 89.2733 | BS7: 81.1766 | BT7: 95.5738 | BU7: 86.3954 | BV7: 85.7252 | BW7: 81.7873 | BX7: 95.1244 | BY7: 84.5258 | BZ7: 87.7824 | CA7: 85.2761 | CB7: 84.2654 | CC7: 84.5172 | CD7: 81.8761 | CE7: 79.8581 | CF7: 84.955 | CG7: 81.206 | CH7: 85.8751 | CI7: 85.0483 | CJ7: 78.3766 | CK7: 89.3002 | CL7: 83.447 | CM7: 83.9606 | CN7: 84.8941 | CO7: 91.0918 | CP7: 87.226 | CQ7: 83.0695 | CR7: 84.2492 | CS7: 74.1822 | CT7: 69.6266 | CU7: 72.0417 | CV7: 72.1142 | CW7: 75.3408 | CX7: 75.5527 | CY7: 77.6063 | CZ7: 76.7055 | DA7: 75.0144 | DB7: 79.2587 | DC7: 78.7065 | DD7: 78.7065 | DE7: 75.3161 | DF7: 78.843 | DG7: 84.0601 | DH7: 77.2559 | DI7: 90.9842 | DJ7: 90.9842 | DK7: 83.2432 | DL7: 90.7244 | DM7: 85.3113 | DN7: 87.6342 | DO7: 93.0185 | DP7: 84.0068 | DQ7: 90.5337 | DR7: 85.7276 | DS7: 84.4596 | DT7: 88.5232 | DU7: 85.5203 | DV7: 82.3361 | DW7: 82.3361 | DX7: 85.0299
A8: 611.433 | B8: 65.5879 | C8: 75.7033 | D8: 71.2436 | E8: 79.3791 | F8: 80.9251 | G8: 83.8509 | H8: 85.8798 | I8: 93.6603 | J8: 94.5603 | K8: 78.1665 | L8: 70.2109 | M8: 65.6427 | N8: 69.5039 | O8: 90.4506 | P8: 82.1327 | Q8: 88.7813 | R8: 51.6093 | S8: 63.68 | T8: 61.9505 | U8: 66.883 | V8: 65.5707 | W8: 78.4812 | X8: 78.0494 | Y8: 88.0397 | Z8: 88.6351 | AA8: 86.4685 | AB8: 86.0564 | AC8: 82.1327 | AD8: 85.0214 | AE8: 93.8669 | AF8: 89.5384 | AG8: 71.0966 | AH8: 67.6543 | AI8: 63.4717 | AJ8: 67.9044 | AK8: 74.2768 | AL8: 65.9676 | AM8: 66.3923 | AN8: 63.1992 | AO8: 74.1619 | AP8: 75.0448 | AQ8: 70.4072 | AR8: 69.2444 | AS8: 85.6847 | AT8: 87.6815 | AU8: 89.8649 | AV8: 89.1691 | AW8: 92.7008 | AX8: 94.0779 | AY8: 96.7256 | AZ8: 92.2166 | BA8: 92.5212 | BB8: 88.7304 | BC8: 91.6063 | BD8: 92.508 | BE8: 95.0622 | BF8: 94.9232 | BG8: 92.3411 | BH8: 90.329 | BI8: 102.888 | BJ8: 102.419 | BK8: 102.549 | BL8: 100.533 | BM8: 94.7541 | BN8: 93.0699 | BO8: 98.7145 | BP8: 97.2789 | BQ8: 99.4396 | BR8: 89.3817 | BS8: 81.2872 | BT8: 95.6863 | BU8: 86.1492 | BV8: 85.7437 | BW8: 81.1435 | BX8: 95.2282 | BY8: 84.4202 | BZ8: 87.8761 | CA8: 85.107 | CB8: 84.063 | CC8: 84.9647 | CD8: 81.9425 | CE8: 79.6976 | CF8: 85.186 | CG8: 81.0467 | CH8: 85.6353 | CI8: 85.1243 | CJ8: 78.5917 | CK8: 89.5362 | CL8: 83.7276 | CM8: 83.8911 | CN8: 85.0991 | CO8: 91.0534 | CP8: 87.2767 | CQ8: 83.1812 | CR8: 84.5206 | CS8: 74.1245 | CT8: 69.9794 | CU8: 71.6682 | CV8: 72.0768 | CW8: 75.0435 | CX8: 75.1397 | CY8: 77.6055 | CZ8: 76.8561 | DA8: 75.2851 | DB8: 79.1079 | DC8: 78.6696 | DD8: 78.6696 | DE8: 75.0224 | DF8: 79.4072 | DG8: 84.1887 | DH8: 77.229 | DI8: 91.4459 | DJ8: 91.4459 | DK8: 84.0366 | DL8: 90.7904 | DM8: 85.5033 | DN8: 88.0671 | DO8: 93.5099 | DP8: 84.0933 | DQ8: 90.6478 | DR8: 86.57 | DS8: 84.9894 | DT8: 88.6636 | DU8: 85.7187 | DV8: 83.1237 | DW8: 83.1237 | DX8: 85.5757
A9: 613.297 | B9: 66.0354 | C9: 73.7957 | D9: 70.0392 | E9: 80.2673 | F9: 80.7233 | G9: 84.235 | H9: 90.1207 | I9: 91.9053 | J9: 94.8696 | K9: 84.6055 | L9: 71.1407 | M9: 64.3832 | N9: 69.9082 | O9: 88.3789 | P9: 81.408 | Q9: 86.9996 | R9: 62.9885 | S9: 65.0052 | T9: 63.1331 | U9: 69.2944 | V9: 66.9232 | W9: 80.2109 | X9: 79.6735 | Y9: 86.994 | Z9: 86.7224 | AA9: 87.9249 | AB9: 86.7592 | AC9: 80.0527 | AD9: 86.0183 | AE9: 95.0561 | AF9: 89.1475 | AG9: 71.5981 | AH9: 69.247 | AI9: 64.0279 | AJ9: 70.1487 | AK9: 75.9434 | AL9: 67.4254 | AM9: 64.7242 | AN9: 64.9325 | AO9: 74.7316 | AP9: 76.6259 | AQ9: 72.3534 | AR9: 73.0706 | AS9: 85.7658 | AT9: 87.678 | AU9: 89.7834 | AV9: 88.9459 | AW9: 93.0578 | AX9: 94.0245 | AY9: 96.468 | AZ9: 91.5983 | BA9: 92.7829 | BB9: 88.407 | BC9: 91.8603 | BD9: 92.6186 | BE9: 94.9213 | BF9: 95.0007 | BG9: 92.179 | BH9: 90.3241 | BI9: 102.932 | BJ9: 102.413 | BK9: 102.351 | BL9: 100.875 | BM9: 94.8553 | BN9: 93.5349 | BO9: 98.1939 | BP9: 97.6113 | BQ9: 99.5554 | BR9: 89.3598 | BS9: 81.2758 | BT9: 95.211 | BU9: 86.0689 | BV9: 85.3764 | BW9: 81.1374 | BX9: 95.461 | BY9: 84.3744 | BZ9: 87.4852 | CA9: 85.031 | CB9: 83.8715 | CC9: 84.859 | CD9: 82.0418 | CE9: 79.9213 | CF9: 85.6078 | CG9: 81.0483 | CH9: 85.4236 | CI9: 85.2792 | CJ9: 78.4271 | CK9: 89.8243 | CL9: 83.7076 | CM9: 83.6643 | CN9: 85.3651 | CO9: 91.2646 | CP9: 87.2421 | CQ9: 83.4831 | CR9: 84.8097 | CS9: 73.7779 | CT9: 70.0423 | CU9: 71.668 | CV9: 71.4125 | CW9: 75.0868 | CX9: 74.9734 | CY9: 77.5684 | CZ9: 76.6208 | DA9: 75.2392 | DB9: 79.0618 | DC9: 79.1881 | DD9: 79.1881 | DE9: 74.8855 | DF9: 79.5038 | DG9: 84.2717 | DH9: 77.1747 | DI9: 91.6543 | DJ9: 91.6543 | DK9: 84.7206 | DL9: 91.4051 | DM9: 85.9625 | DN9: 88.3817 | DO9: 93.6148 | DP9: 84.2249 | DQ9: 90.9906 | DR9: 86.6459 | DS9: 84.9707 | DT9: 88.6678 | DU9: 85.7668 | DV9: 83.3434 | DW9: 83.3434 | DX9: 86.7165
A10: 615.161 | B10: 66.8188 | C10: 73.3476 | D10: 70.0201 | E10: 79.676 | F10: 78.5547 | G10: 83.8787 | H10: 89.4775 | I10: 90.9397 | J10: 96.0263 | K10: 81.901 | L10: 71.2284 | M10: 64.3751 | N10: 70.7373 | O10: 88.5806 | P10: 83.0303 | Q10: 87.2911 | R10: 70.8622 | S10: 65.235 | T10: 64.5056 | U10: 69.9776 | V10: 68.8921 | W10: 82.1271 | X10: 79.4619 | Y10: 88.1121 | Z10: 84.6635 | AA10: 88.2162 | AB10: 85.9756 | AC10: 80.8354 | AD10: 85.9783 | AE10: 92.9079 | AF10: 86.7864 | AG10: 71.9096 | AH10: 69.8916 | AI10: 65.7422 | AJ10: 70.0445 | AK10: 77.1898 | AL10: 67.2704 | AM10: 64.0833 | AN10: 65.9071 | AO10: 76.688 | AP10: 77.813 | AQ10: 73.3527 | AR10: 73.4364 | AS10: 85.4519 | AT10: 87.707 | AU10: 89.7267 | AV10: 88.805 | AW10: 93.1169 | AX10: 93.8891 | AY10: 96.1528 | AZ10: 91.686 | BA10: 92.4601 | BB10: 88.1057 | BC10: 91.6736 | BD10: 93.084 | BE10: 94.84 | BF10: 94.9198 | BG10: 92.207 | BH10: 90.2354 | BI10: 102.848 | BJ10: 102.698 | BK10: 102.142 | BL10: 100.926 | BM10: 95.2692 | BN10: 93.5055 | BO10: 98.4615 | BP10: 98.0668 | BQ10: 99.4297 | BR10: 89.2609 | BS10: 81.4529 | BT10: 95.2385 | BU10: 85.9892 | BV10: 85.331 | BW10: 81.4826 | BX10: 95.3226 | BY10: 84.5643 | BZ10: 87.3994 | CA10: 84.9785 | CB10: 83.919 | CC10: 84.8837 | CD10: 82.2624 | CE10: 79.8634 | CF10: 85.5925 | CG10: 81.1152 | CH10: 85.6095 | CI10: 85.5283 | CJ10: 78.4195 | CK10: 90.2914 | CL10: 84.0077 | CM10: 83.7181 | CN10: 85.3789 | CO10: 91.0835 | CP10: 87.5969 | CQ10: 83.7369 | CR10: 84.9623 | CS10: 73.7229 | CT10: 70.0762 | CU10: 71.5148 | CV10: 71.6215 | CW10: 75.4525 | CX10: 74.8869 | CY10: 77.2705 | CZ10: 76.8674 | DA10: 75.0154 | DB10: 79.2236 | DC10: 79.2624 | DD10: 79.2624 | DE10: 74.8412 | DF10: 78.9812 | DG10: 84.2497 | DH10: 77.1 | DI10: 91.9509 | DJ10: 91.9509 | DK10: 84.8175 | DL10: 91.7453 | DM10: 86.2657 | DN10: 88.7113 | DO10: 93.4023 | DP10: 84.4133 | DQ10: 91.3744 | DR10: 86.9538 | DS10: 84.9878 | DT10: 89.0516 | DU10: 86.6611 | DV10: 83.7711 | DW10: 83.7711 | DX10: 87.1965
A11: 617.025 | B11: 67.0669 | C11: 74.4928 | D11: 70.3122 | E11: 79.8762 | F11: 78.3416 | G11: 84.5312 | H11: 90.4935 | I11: 92.7581 | J11: 96.5962 | K11: 78.193 | L11: 73.0205 | M11: 66.6383 | N11: 71.1134 | O11: 89.0745 | P11: 84.3524 | Q11: 87.8801 | R11: 72.0574 | S11: 65.6721 | T11: 65.5052 | U11: 69.9006 | V11: 70.2568 | W11: 84.1468 | X11: 81.4376 | Y11: 91.8005 | Z11: 88.011 | AA11: 89.0991 | AB11: 87.9546 | AC11: 82.4742 | AD11: 85.3895 | AE11: 92.1232 | AF11: 87.2291 | AG11: 71.7535 | AH11: 67.6963 | AI11: 66.5523 | AJ11: 69.5857 | AK11: 76.8165 | AL11: 66.4712 | AM11: 66.0436 | AN11: 67.3998 | AO11: 76.466 | AP11: 78.1607 | AQ11: 72.6223 | AR11: 72.9334 | AS11: 84.6007 | AT11: 87.2707 | AU11: 89.3753 | AV11: 88.5006 | AW11: 92.731 | AX11: 93.6994 | AY11: 96.3582 | AZ11: 92.0281 | BA11: 92.1918 | BB11: 87.9606 | BC11: 91.0959 | BD11: 92.7256 | BE11: 94.5143 | BF11: 94.6572 | BG11: 92.4275 | BH11: 89.8134 | BI11: 102.225 | BJ11: 102.676 | BK11: 101.925 | BL11: 100.438 | BM11: 95.4617 | BN11: 93.1942 | BO11: 98.5512 | BP11: 97.9513 | BQ11: 99.1415 | BR11: 88.7475 | BS11: 81.0231 | BT11: 94.866 | BU11: 85.5384 | BV11: 84.9612 | BW11: 81.2307 | BX11: 94.6905 | BY11: 84.2236 | BZ11: 87.3586 | CA11: 84.869 | CB11: 83.9662 | CC11: 84.1633 | CD11: 81.7621 | CE11: 79.3696 | CF11: 84.8689 | CG11: 80.886 | CH11: 85.4808 | CI11: 85.0993 | CJ11: 78.2957 | CK11: 90.1546 | CL11: 83.6867 | CM11: 83.2703 | CN11: 85.3908 | CO11: 90.7794 | CP11: 87.4939 | CQ11: 83.6023 | CR11: 84.4335 | CS11: 73.3831 | CT11: 69.6618 | CU11: 71.1049 | CV11: 70.8774 | CW11: 75.2505 | CX11: 74.5208 | CY11: 76.1324 | CZ11: 76.7076 | DA11: 75.0272 | DB11: 78.8894 | DC11: 78.9617 | DD11: 78.9617 | DE11: 74.5092 | DF11: 78.3912 | DG11: 83.9338 | DH11: 77.0078 | DI11: 92.041 | DJ11: 92.041 | DK11: 84.3419 | DL11: 91.7052 | DM11: 86.104 | DN11: 88.7815 | DO11: 93.2308 | DP11: 83.7092 | DQ11: 91.4372 | DR11: 87.3186 | DS11: 85.1983 | DT11: 88.8454 | DU11: 86.9432 | DV11: 83.5113 | DW11: 83.5113 | DX11: 86.7424
A12: 618.889 | B12: 67.854 | C12: 75.6191 | D12: 71.6311 | E12: 80.4385 | F12: 77.5481 | G12: 84.4599 | H12: 87.472 | I12: 91.8373 | J12: 95.7248 | K12: 83.1516 | L12: 73.6048 | M12: 67.5858 | N12: 72.671 | O12: 90.6297 | P12: 85.2194 | Q12: 88.9398 | R12: 63.769 | S12: 66.7302 | T12: 64.8592 | U12: 71.4581 | V12: 70.0078 | W12: 84.7556 | X12: 82.3991 | Y12: 92.2433 | Z12: 87.4408 | AA12: 88.7287 | AB12: 88.6171 | AC12: 83.9026 | AD12: 84.7386 | AE12: 92.5037 | AF12: 89.34 | AG12: 73.838 | AH12: 68.2971 | AI12: 64.8988 | AJ12: 69.8338 | AK12: 75.4724 | AL12: 66.9691 | AM12: 67.368 | AN12: 66.5424 | AO12: 78.816 | AP12: 78.1303 | AQ12: 74.2214 | AR12: 72.6726 | AS12: 84.8337 | AT12: 87.2353 | AU12: 89.2752 | AV12: 88.3813 | AW12: 92.6814 | AX12: 94.1213 | AY12: 96.9143 | AZ12: 91.6396 | BA12: 92.3561 | BB12: 88.1297 | BC12: 91.1368 | BD12: 92.4513 | BE12: 94.7717 | BF12: 94.3019 | BG12: 91.7378 | BH12: 89.9505 | BI12: 101.505 | BJ12: 102.247 | BK12: 102.206 | BL12: 100.507 | BM12: 94.8563 | BN12: 92.9905 | BO12: 97.9826 | BP12: 97.7599 | BQ12: 99.6702 | BR12: 88.653 | BS12: 80.9638 | BT12: 94.1911 | BU12: 85.5932 | BV12: 84.5017 | BW12: 80.7577 | BX12: 94.5641 | BY12: 83.6724 | BZ12: 87.0153 | CA12: 84.7038 | CB12: 83.9787 | CC12: 83.0161 | CD12: 80.6518 | CE12: 78.9182 | CF12: 84.7592 | CG12: 81.0307 | CH12: 85.1821 | CI12: 84.3827 | CJ12: 77.5316 | CK12: 89.6059 | CL12: 83.2742 | CM12: 83.0875 | CN12: 84.9242 | CO12: 90.9449 | CP12: 86.8199 | CQ12: 83.159 | CR12: 84.0839 | CS12: 73.5713 | CT12: 69.5101 | CU12: 71.3711 | CV12: 71.1105 | CW12: 75.0053 | CX12: 74.3983 | CY12: 76.3204 | CZ12: 76.467 | DA12: 75.4173 | DB12: 78.6153 | DC12: 78.8087 | DD12: 78.8087 | DE12: 74.5492 | DF12: 78.5187 | DG12: 83.9124 | DH12: 76.9645 | DI12: 92.2001 | DJ12: 92.2001 | DK12: 84.2137 | DL12: 91.9474 | DM12: 85.9324 | DN12: 88.2412 | DO12: 93.2271 | DP12: 83.921 | DQ12: 91.0403 | DR12: 87.0636 | DS12: 85.0934 | DT12: 88.8753 | DU12: 86.5677 | DV12: 83.4782 | DW12: 83.4782 | DX12: 86.2466
A13: 620.753 | B13: 67.8927 | C13: 76.3603 | D13: 73.638 | E13: 80.3326 | F13: 78.3385 | G13: 84.525 | H13: 90.786 | I13: 90.6933 | J13: 95.4787 | K13: 83.1919 | L13: 73.2485 | M13: 66.5705 | N13: 73.9018 | O13: 91.3389 | P13: 85.983 | Q13: 90.289 | R13: 54.6207 | S13: 66.3661 | T13: 63.6148 | U13: 72.1442 | V13: 69.5212 | W13: 83.225 | X13: 80.726 | Y13: 90.1673 | Z13: 87.073 | AA13: 89.0793 | AB13: 88.42 | AC13: 85.4341 | AD13: 84.7721 | AE13: 92.7096 | AF13: 89.1512 | AG13: 72.9785 | AH13: 71.0269 | AI13: 65.6799 | AJ13: 69.7809 | AK13: 75.4512 | AL13: 69.3151 | AM13: 68.0081 | AN13: 66.587 | AO13: 81.1953 | AP13: 78.0928 | AQ13: 75.1452 | AR13: 72.9233 | AS13: 85.1679 | AT13: 87.493 | AU13: 89.1552 | AV13: 88.2152 | AW13: 92.845 | AX13: 94.0934 | AY13: 96.8088 | AZ13: 91.532 | BA13: 92.3754 | BB13: 87.9843 | BC13: 91.2079 | BD13: 92.7171 | BE13: 94.942 | BF13: 94.2117 | BG13: 91.5718 | BH13: 90.0165 | BI13: 101.826 | BJ13: 101.938 | BK13: 102.318 | BL13: 100.73 | BM13: 94.77 | BN13: 93.1162 | BO13: 97.6064 | BP13: 98.0109 | BQ13: 99.8247 | BR13: 88.8774 | BS13: 81.3883 | BT13: 94.7142 | BU13: 85.855 | BV13: 85.0445 | BW13: 81.0491 | BX13: 94.9437 | BY13: 83.9391 | BZ13: 87.1223 | CA13: 85.1244 | CB13: 84.1206 | CC13: 83.4658 | CD13: 81.1014 | CE13: 78.5404 | CF13: 84.8293 | CG13: 80.8615 | CH13: 85.0718 | CI13: 84.7058 | CJ13: 77.792 | CK13: 89.8395 | CL13: 83.3306 | CM13: 83.2011 | CN13: 84.7645 | CO13: 91.0409 | CP13: 87.2651 | CQ13: 83.0663 | CR13: 84.3975 | CS13: 74.0434 | CT13: 70.0483 | CU13: 71.7858 | CV13: 71.0967 | CW13: 75.2852 | CX13: 74.747 | CY13: 77.1499 | CZ13: 76.8371 | DA13: 75.5919 | DB13: 78.9692 | DC13: 78.6854 | DD13: 78.6854 | DE13: 74.7387 | DF13: 78.855 | DG13: 83.9722 | DH13: 77.133 | DI13: 92.2555 | DJ13: 92.2555 | DK13: 84.6342 | DL13: 91.8108 | DM13: 86.1519 | DN13: 88.2026 | DO13: 93.4792 | DP13: 84.8741 | DQ13: 90.945 | DR13: 87.2414 | DS13: 85.4486 | DT13: 89.3082 | DU13: 86.7561 | DV13: 83.7928 | DW13: 83.7928 | DX13: 86.4922
... A1799: 3950.08 | B1799: 99.3385 | C1799: 99.7942 | D1799: 99.9123 | E1799: 100.855 | F1799: 100.069 | G1799: 99.0932 | H1799: 100.158 | I1799: 100.7 | J1799: 100.875 | K1799: 100.766 | L1799: 100.429 | M1799: 99.5519 | N1799: 100.049 | O1799: 100.934 | P1799: 100.496 | Q1799: 100.661 | R1799: 98.8387 | S1799: 99.0487 | T1799: 100.312 | U1799: 100.59 | V1799: 100.755 | W1799: 100.307 | X1799: 98.8828 | Y1799: 100.463 | Z1799: 100.705 | AA1799: 100.059 | AB1799: 99.7361 | AC1799: 99.8647 | AD1799: 99.8143 | AE1799: 99.6919 | AF1799: 99.813 | AG1799: 100.064 | AH1799: 100.198 | AI1799: 99.6604 | AJ1799: 100.26 | AK1799: 100.481 | AL1799: 98.9834 | AM1799: 99.7566 | AN1799: 99.6432 | AO1799: 100.264 | AP1799: 100.203 | AQ1799: 100.17 | AR1799: 99.2983 | AS1799: 99.8473 | AT1799: 100.967 | AU1799: 100.902 | AV1799: 100.012 | AW1799: 101.037 | AX1799: 101.07 | AY1799: 101.151 | AZ1799: 100.09 | BA1799: 100.069 | BB1799: 99.3632 | BC1799: 100.358 | BD1799: 100.381 | BE1799: 100.592 | BF1799: 100.947 | BG1799: 99.6119 | BH1799: 100.664 | BI1799: 100.966 | BJ1799: 101.577 | BK1799: 101.76 | BL1799: 101.079 | BM1799: 100.321 | BN1799: 100.837 | BO1799: 101.355 | BP1799: 100.542 | BQ1799: 101.206 | BR1799: 99.6888 | BS1799: 98.797 | BT1799: 101.516 | BU1799: 101.263 | BV1799: 100.458 | BW1799: 100.504 | BX1799: 101.625 | BY1799: 100.13 | BZ1799: 101.303 | CA1799: 100.67 | CB1799: 99.6876 | CC1799: 100.4 | CD1799: 99.6351 | CE1799: 99.1762 | CF1799: 99.7878 | CG1799: 99.2253 | CH1799: 100.118 | CI1799: 99.7371 | CJ1799: 98.3451 | CK1799: 98.9958 | CL1799: 99.6315 | CM1799: 98.8089 | CN1799: 99.0463 | CO1799: 100.878 | CP1799: 100.049 | CQ1799: 99.398 | CR1799: 99.7776 | CS1799: 99.2258 | CT1799: 97.3098 | CU1799: 98.6089 | CV1799: 97.8686 | CW1799: 97.7057 | CX1799: 97.9347 | CY1799: 97.8502 | CZ1799: 97.9069 | DA1799: 98.1709 | DB1799: 99.065 | DC1799: 98.3529 | DD1799: 98.3529 | DE1799: 97.9384 | DF1799: 98.2247 | DG1799: 98.7109 | DH1799: 97.9676 | DI1799: 100.134 | DJ1799: 100.134 | DK1799: 98.6702 | DL1799: 100.007 | DM1799: 99.3204 | DN1799: 99.4288 | DO1799: 100.258 | DP1799: 99.7856 | DQ1799: 101.046 | DR1799: 100.415 | DS1799: 99.3118 | DT1799: 100.669 | DU1799: 99.3229 | DV1799: 99.0358 | DW1799: 99.0358 | DX1799: 100.64
A1800: 3951.94 | B1800: 99.4056 | C1800: 99.7822 | D1800: 99.9314 | E1800: 100.891 | F1800: 100.094 | G1800: 99.113 | H1800: 100.198 | I1800: 100.745 | J1800: 100.872 | K1800: 100.784 | L1800: 100.418 | M1800: 99.5877 | N1800: 100.045 | O1800: 100.936 | P1800: 100.466 | Q1800: 100.679 | R1800: 98.8964 | S1800: 99.037 | T1800: 100.301 | U1800: 100.631 | V1800: 100.77 | W1800: 100.299 | X1800: 98.8646 | Y1800: 100.452 | Z1800: 100.716 | AA1800: 100.041 | AB1800: 99.7339 | AC1800: 99.8191 | AD1800: 99.8277 | AE1800: 99.6916 | AF1800: 99.8166 | AG1800: 100.064 | AH1800: 100.217 | AI1800: 99.6299 | AJ1800: 100.26 | AK1800: 100.495 | AL1800: 98.9509 | AM1800: 99.7591 | AN1800: 99.6232 | AO1800: 100.243 | AP1800: 100.234 | AQ1800: 100.159 | AR1800: 99.2801

Sheet XRF suelo
A1: Numero | B1: Nº en cronosecuencia | C1: Nombre ubicacion | D1: Codigo | E1: % SiO2 | F1: %TiO2 | G1: %Al2O3 | H1: %Fe2O3 | I1: %MnO | J1: %MgO | K1: %CaO | L1: %Na2O | M1: %K2O | N1: %P2O5 | O1: %BaO | P1: %Cr2O3 | Q1: %SO3 | R1: %V2O5 | S1: %ZnO5 | T1: %ZrO2 | U1: %SrO | V1: %Rb2O | W1: %PbO | X1: %As2O3
A2: 1 | B2: 1 | C2: Bellingshausen Dome | D2: BH1.1 | E2: 50.962373 | F2: 0.74397625 | G2: 21.296644 | H2: 7.382733 | I2: 0.14905448 | J2: 7.6575117 | K2: 9.7883426 | L2: 1.493137 | M2: 0.11924358 | N2: 0.090728812 | O2: 0.010369007 | P2: 0.0090728812 | Q2: 0.18793825 | R2: 0.011665133 | S2: 0.012961259 | T2: 0.014257385 | U2: 0.064806294 | V2: 0.0025922518 | W2: 0.0012961259 | X2: 0.0012961259
A3: 2 | B3: 2 | C3: Bellingshausen Dome | D3: BH1.2 | E3: 47.604079 | F3: 0.97799379 | G3: 19.968807 | H3: 7.733959 | I3: 0.17071881 | J3: 6.9571222 | K3: 7.5129509 | L3: 1.5748479 | M3: 0.55450527 | N3: 0.10057852 | O3: 0.027791434 | P3: 0.0079404096 | Q3: 0.19321663 | R3: 0.015880819 | S3: 0.014557418 | T3: 0.015880819 | U3: 0.059553072 | V3: 0.0039702048 | W3: 0.0013234016 | X3: 0.0013234016
A4: 3 | B4: 3 | C4: Bellingshausen Dome | D4: BH1.3 | E4: 49.878489 | F4: 1.2540393 | G4: 18.319821 | H4: 8.4555057 | I4: 0.19313264 | J4: 6.5956119 | K4: 6.2529999 | L4: 1.8096264 | M4: 0.39287941 | N4: 0.14021959 | O4: 0.022488047 | P4: 0.01058261 | Q4: 0.18916416 | R4: 0.019842395 | S4: 0.015873916 | T4: 0.017196742 | U4: 0.052913052 | V4: 0.0039684789 | W4: 0.0013228263 | X4: 0.0013228263
A5: 4 | B5: 4 | C5: Bellingshausen Dome | D5: BH1.4 | E5: 52.589769 | F5: 1.211316 | G5: 18.298491 | H5: 8.2243362 | I5: 0.19312738 | J5: 6.5558207 | K5: 6.124897 | L5: 1.7013603 | M5: 0.32187897 | N5: 0.1116723 | O5: 0.024962043 | P5: 0.014451709 | Q5: 0.18655843 | R5: 0.019706876 | S5: 0.015765501 | T5: 0.017079292 | U5: 0.051237877 | V5: 0.0039413752 | W5: 0.0013137917 | X5: 0.0013137917
A6: 5 | B6: 1 | C6: Bellingshausen Dome | D6: BH2.1 | E6: 64.943005 | F6: 1.4768093 | G6: 19.474949 | H6: 7.5746433 | I6: 0.16913884 | J6: 4.3748898 | K6: 6.9851818 | L6: 3.5923071 | M6: 0.73461796 | N6: 0.33196654 | O6: 0.034080215 | P6: 0.0075733811 | Q6: 0.18681007 | R6: 0.022720143 | S6: 0.016408992 | T6: 0.018933453 | U6: 0.041653596 | V6: 0.0037866905 | W6: 0.0012622302 | X6: 0.0012622302
A7: 6 | B7: 2 | C7: Bellingshausen Dome | D7: BH2.2 | E7: 55.14348 | F7: 1.5157787 | G7: 17.215009 | H7: 7.7646059 | I7: 0.18178882 | J7: 4.7095075 | K7: 6.7981171 | L7: 2.3724095 | M7: 0.79254694 | N7: 0.25371965 | O7: 0.032695831 | P7: 0.0039234997 | Q7: 0.19355932 | R7: 0.023540998 | S7: 0.017001832 | T7: 0.019617498 | U7: 0.041850663 | V7: 0.0052313329 | W7: 0.0013078332 | X7: 0.0013078332
A8: 7 | B8: 3 | C8: Bellingshausen Dome | D8: BH2.3 | E8: 60.547854 | F8: 1.6013161 | G8: 19.421058 | H8: 8.3775863 | I8: 0.18486532 | J8: 4.8676951 | K8: 6.3032699 | L8: 2.9348963 | M8: 1.088793 | N8: 0.30470904 | O8: 0.040797863 | P8: 0.0038247997 | Q8: 0.18869012 | R8: 0.024223731 | S8: 0.016574132 | T8: 0.019123998 | U8: 0.042072797 | V8: 0.0050997329 | W8: 0.0012749332 | X8: 0.0012749332
A9: 8 | B9: 4 | C9: Bellingshausen Dome | D9: BH2.4 | E9: 58.105212 | F9: 1.4971927 | G9: 19.074106 | H9: 8.1272501 | I9: 0.18506072 | J9: 4.7087673 | K9: 6.5400974 | L9: 3.3567959 | M9: 0.80707038 | N9: 0.26473965 | O9: 0.032128598 | P9: 0.0077108635 | Q9: 0.1902013 | R9: 0.023132591 | S9: 0.016706871 | T9: 0.019277159 | U9: 0.041124605 | V9: 0.0038554318 | W9: 0.0012851439 | X9: 0.0012851439
A10: 9 | B10: 1 | C10: Marian Cove | D10: MC.1.1 | E10: 57.821279 | F10: 2.1262036 | G10: 22.634519 | H10: 9.5895601 | I10: 0.17951779 | J10: 4.6152623 | K10: 3.9442986 | L10: 2.5234344 | M10: 2.4776001 | N10: 0.33611841 | O10: 0.029283043 | P10: 0.011458582 | Q10: 0.17569826 | R10: 0.033102571 | S10: 0.017824461 | T10: 0.020370813 | U10: 0.029283043 | V10: 0.0076390548 | W10: 0.0012731758 | X10: 0.0012731758
A11: 10 | B11: 2 | C11: Marian Cove | D11: MC.1.2 | E11: 57.352444 | F11: 1.6896141 | G11: 25.5267 | H11: 8.8589886 | I11: 0.16462252 | J11: 3.4889765 | K11: 2.1936908 | L11: 2.2192136 | M11: 3.5553359 | N11: 0.27437086 | O11: 0.058702603 | P11: 0.012761436 | Q11: 0.18248853 | R11: 0.026799015 | S11: 0.016589866 | T11: 0.019142153 | U11: 0.026799015 | V11: 0.010209148 | W11: 0.0012761436 | X11: 0.0012761436
A12: 11 | B12: 3 | C12: Marian Cove | D12: MC.1.3 | E12: 52.115605 | F12: 1.6738047 | G12: 23.215956 | H12: 10.569288 | I12: 0.20308141 | J12: 5.536232 | K12: 2.2545917 | L12: 2.0967832 | M12: 2.5456319 | N12: 0.22895165 | O12: 0.042685901 | P12: 0.012935122 | Q12: 0.18367873 | R12: 0.025870243 | S12: 0.019402682 | T12: 0.01810917 | U12: 0.02975078 | V12: 0.0090545851 | W12: 0.0012935122 | X12: 0.0012935122
A13: 12 | B13: 4 | C13: Marian Cove | D13: MC.1.4 | E13: 56.401548 | F13: 1.3032466 | G13: 27.957774 | H13: 8.4116322 | I13: 0.18416832 | J13: 2.2445514 | K13: 1.3403361 | L13: 1.5257834 | M13: 4.891971 | N13: 0.30055247 | O13: 0.029415773 | P13: 0.0051157866 | Q13: 0.15858939 | R13: 0.020463147 | S13: 0.017905253 | T13: 0.017905253 | U13: 0.025578933 | V13: 0.01534736 | W13: 0.0025578933 | X13: 0.0025578933
... A29: 28 | B29: 4 | C29: Potter Peninsula | D29: PP1.4 | E29: 48.872631 | F29: 1.5199817 | G29: 14.505588 | H29: 8.894808 | I29: 0.16542173 | J29: 4.8528228 | K29: 5.3273934 | L29: 1.6189635 | M29: 0.84202374 | N29: 0.18033681 | O29: 0.03254198 | P29: 0.013559159 | Q29: 0.18576047 | R29: 0.024406485 | S29: 0.017626906 | T29: 0.021694654 | U29: 0.059660298 | V29: 0.0040677476 | W29: 0.0013559159 | X29: 0.0013559159

Sheet Analisis de agua (Multipara)
A1: Numero | B1: Nº en cronosecuencia | C1: Nombre ubicacion | D1: Codigo | E1: Rep | F1: pH | G1: ORP | H1: DO | I1: Cond | J1: Resist | K1: TDS | L1: Salinity | M1: Seawater | N1: atm | O1: T | P1: FeLow | Q1: FeHigh | R1: MnHigh | S1: PMULow | T1: PHighRange
A2: 1 | B2: 1 | C2: Bellingshausen Dome | D2: BH1.1 | E2: 1 | F2: 7.1 | G2: 257.24 | H2: 11.47 | I2: 100.6 | J2: 9956 | K2: 50.2 | L2: 0.05 | M2: 0 | N2: 0.98 | O2: 10.5 | P2: 476 | Q2: 0.22 | R2: 0.22 | S2: 200 | T2: 0.4
E3: 2 | F3: 7.25 | G3: 253.37 | H3: 11.74 | I3: 71.4 | J3: 13996.8 | K3: 36 | L3: 0.03 | M3: 0 | N3: 0.98 | O3: 9.75 | P3: 690 | Q3: 0.14 | R3: 0.14 | S3: 200 | T3: 0.3
E4: 3 | F4: 7.31 | G4: 259.13 | H4: 11.22 | I4: 58.85 | J4: 16927.45 | K4: 29.45 | L4: 0.03 | M4: 0 | N4: 0.98 | O4: 11.46 | P4: 280 | Q4: 0.18 | R4: 0.18 | S4: 200 | T4: 0.3
A5: 2 | B5: 2 | C5: Bellingshausen Dome | D5: BH1.2 | E5: 1 | F5: 7.54 | G5: 283.42 | H5: 12.04 | I5: 76.73 | J5: 13022.95 | K5: 38.55 | L5: 0.04 | M5: 0.04 | N5: 0.98 | O5: 9.86 | P5: 355 | Q5: 0 | R5: 0 | S5: 28 | T5: 0.2
E6: 2 | F6: 7.42 | G6: 278.53 | H6: 11.7 | I6: 75.88 | J6: 13156.67 | K6: 38 | L6: 0.04 | M6: 0.04 | N6: 0.98 | O6: 10.2 | P6: 333 | Q6: 0 | R6: 0 | S6: 28 | T6: 0.1
E7: 3 | F7: 7.43 | G7: 279.93 | H7: 11.53 | I7: 77 | J7: 12996.82 | K7: 38.14 | L7: 0.04 | M7: 0.04 | N7: 0.98 | O7: 11.43 | P7: 300 | Q7: 0 | R7: 0 | S7: 30 | T7: 0.3
A8: 3 | B8: 3 | C8: Bellingshausen Dome | D8: BH1.3 | E8: 1 | F8: 7.79 | G8: 266.06 | H8: 12.38 | I8: 76.85 | J8: 13032.96 | K8: 38 | L8: 0.04 | M8: 0.04 | N8: 0.98 | O8: 10.12 | P8: 53 | Q8: 0.11 | R8: 0.11 | S8: 40 | T8: 0.2
E9: 2 | F9: 7.71 | G9: 278.07 | H9: 11.76 | I9: 78.04 | J9: 12838.07 | K9: 38.96 | L9: 0.04 | M9: 0.04 | N9: 0.98 | O9: 10.76 | P9: 610 | Q9: 0.2 | R9: 0.2 | S9: 30 | T9: 0.3
E10: 3 | F10: 7.76 | G10: 277.77 | H10: 11.48 | I10: 79 | J10: 12628.41 | K10: 40 | L10: 0.04 | M10: 0.04 | N10: 0.98 | O10: 11.45 | P10: 730 | Q10: 0.16 | R10: 0.16 | S10: 35 | T10: 0.3
A11: 4 | B11: 4 | C11: Bellingshausen Dome | D11: BH1.4 | E11: 1 | F11: 7.72 | G11: 286.99 | H11: 11.32 | I11: 107.69 | J11: 9281.62 | K11: 53.86 | L11: 0.05 | M11: 0.04 | N11: 0.98 | O11: 11.5 | P11: 160 | Q11: 0 | R11: 0 | S11: 23 | T11: 0.3
E12: 2 | F12: 7.55 | G12: 289.37 | H12: 11.18 | I12: 116.87 | J12: 8569.83 | K12: 58 | L12: 0.06 | M12: 0.04 | N12: 0.97 | O12: 11.25 | P12: 70 | Q12: 0 | R12: 0 | S12: 22 | T12: 0.4
E13: 3 | F13: 7.29 | G13: 300.84 | H13: 10.97 | I13: 108.08 | J13: 9232.6 | K13: 54 | L13: 0.05 | M13: 0.04 | N13: 0.97 | O13: 12.53 | P13: 120 | Q13: 0 | R13: 0 | S13: 23 | T13: 0.4
A14: 5 | B14: 1 | C14: Bellingshausen Dome | D14: BH2.1 | E14: 1 | F14: 5.25 | G14: 393.91667 | H14: 8.674375 | I14: 6.5 | J14: 5.75 | K14: 156035 | L14: 3.0208333 | M14: 0 | N14: 0.972 | O14: 18.179792 | P14: 90 | Q14: 0 | R14: 0.1 | S14: 107 | T14: 0.6
E15: 2 | F15: 5.3046429 | G15: 390.91786 | H15: 8.7396429 | I15: 5 | J15: 5 | K15: 188817.75 | L15: 3 | M15: 0 | N15: 0.972 | O15: 18.1175 | P15: 50 | Q15: 0 | R15: 0.1 | S15: 100 | T15: 0.7
E16: 3 | F16: 5.3040625 | G16: 389.975 | H16: 8.8209375 | I16: 5 | J16: 4.28125 | K16: 191884.66 | L16: 3 | M16: 0 | N16: 0.972 | O16: 18.094375 | P16: 56 | Q16: 0 | R16: 0.1 | S16: 103 | T16: 0.4
A17: 6 | B17: 2 | C17: Bellingshausen Dome | D17: BH2.2 | E17: 1 | F17: 4.35 | G17: 458.6 | H17: 9.8992308 | I17: 87 | J17: 76 | K17: 11461.115 | L17: 44 | M17: 0.04 | N17: 0.972 | O17: 18.393077 | P17: 510 | Q17: 0.23 | R17: 0 | S17: 41 | T17: 0.1
E18: 2 | F18: 4.34 | G18: 459.68857 | H18: 10.792286 | I18: 90 | J18: 78 | K18: 11119.971 | L18: 45 | M18: 0.04 | N18: 0.972 | O18: 18.103429 | P18: 360 | Q18: 0.26 | R18: 0 | S18: 51 | T18: 0.2
E19: 3 | F19: 4.3408333 | G19: 460.2 | H19: 10.681667 | I19: 91 | J19: 79 | K19: 10945.25 | L19: 46 | M19: 0.04 | N19: 0.972 | O19: 18.048333 | P19: 890 | Q19: 0.25 | R19: 0 | S19: 46 | T19: 0.2
A20: 7 | B20: 3 | C20: Bellingshausen Dome | D20: BH2.3 | E20: 1 | F20: 4.25 | G20: 458.60333 | H20: 11.075 | I20: 93 | J20: 81 | K20: 10726.867 | L20: 47 | M20: 0.04 | N20: 0.972 | O20: 18.042 | P20: 253 | Q20: 0.08 | R20: 0 | S20: 37 | T20: 0.3
E21: 2 | F21: 4.25 | G21: 455.84783 | H21: 11.043261 | I21: 95 | J21: 83 | K21: 10478.717 | L21: 48 | M21: 0.04 | N21: 0.972 | O21: 18.190435 | P21: 235 | Q21: 0.11 | R21: 0 | S21: 33 | T21: 0.2
E22: 3 | F22: 4.2475 | G22: 455.555 | H22: 10.712 | I22: 94 | J22: 82 | K22: 10644.9 | L22: 47 | M22: 0.04 | N22: 0.972 | O22: 18.1975 | P22: 239 | Q22: 0.09 | R22: 0 | S22: 35 | T22: 0.7
A23: 8 | B23: 4 | C23: Bellingshausen Dome | D23: BH2.4 | E23: 1 | F23: 4.3474194 | G23: 429.57742 | H23: 10.68871 | I23: 92 | J23: 80 | K23: 10857.774 | L23: 46 | M23: 0.04 | N23: 0.972 | O23: 18.145806 | P23: 333 | Q23: 0.19 | R23: 0 | S23: 25 | T23: 0
E24: 2 | F24: 4.3495455 | G24: 430.54773 | H24: 10.547045 | I24: 92 | J24: 80 | K24: 10852.75 | L24: 46 | M24: 0.04 | N24: 0.972 | O24: 18.181591 | P24: 330 | Q24: 0.17 | R24: 0 | S24: 46 | T24: 0.5
E25: 3 | F25: 4.3408108 | G25: 433.73243 | H25: 10.646486 | I25: 92 | J25: 80 | K25: 10859.946 | L25: 46 | M25: 0.04 | N25: 0.972 | O25: 18.038919 | P25: 368 | Q25: 0.18 | R25: 0 | S25: 36 | T25: 0.2
A26: 9 | B26: 1 | C26: Marian Cove | D26: MC.1.1 | E26: 1 | F26: 7.6758333 | G26: 294.275 | H26: 11.193333 | I26: 85 | J26: 68 | K26: 11809 | L26: 42 | M26: 0.04 | N26: 0.983 | O26: 14.653333 | P26: 78 | Q26: 0.06 | R26: 0.1 | S26: 103 | T26: 0.2
E27: 2 | F27: 8.091 | G27: 263.19 | H27: 13.159 | I27: 144.9 | J27: 102 | K27: 6914.5 | L27: 72 | M27: 0.07 | N27: 0.983 | O27: 9.47 | P27: 95 | Q27: 0 | R27: 0.2 | S27: 57 | T27: 0.6
E28: 3 | F28: 7.536875 | G28: 298.80625 | H28: 11.57375 | I28: 71 | J28: 58 | K28: 14177.125 | L28: 35 | M28: 0.03 | N28: 0.983 | O28: 15.27375 | P28: 85 | Q28: 0 | R28: 0.1 | S28: 51 | T28: 0.5
A29: 10 | B29: 2 | C29: Marian Cove | D29: MC.1.2 | E29: 1 | F29: 8.06 | G29: 274.7 | H29: 13.215 | I29: 65 | J29: 45 | K29: 15346.5 | L29: 33 | M29: 0.03 | N29: 0.983 | O29: 8.555 | P29: 28 | Q29: 0 | R29: 0.1 | S29: 38 | T29: 0.1
E30: 2 | F30: 7.548 | G30: 286.165 | H30: 12.6275 | I30: 132.35 | J30: 101.75 | K30: 7563.2 | L30: 65.95 | M30: 0.06 | N30: 0.983 | O30: 12.8765 | P30: 64 | Q30: 0.09 | R30: 0 | S30: 25 | T30: 0.3
E31: 3 | F31: 7.4491667 | G31: 285.02917 | H31: 11.489167 | I31: 105.20833 | J31: 86.875 | K31: 9971.0417 | L31: 52.625 | M31: 0.046666667 | N31: 0.983 | O31: 15.910417 | P31: 31 | Q31: 0 | R31: 0 | S31: 44 | T31: 0.3
A32: 11 | B32: 3 | C32: Marian Cove | D32: MC.1.3 | E32: 1 | F32: 7.8889655 | G32: 278.64828 | H32: 12.705862 | I32: 101 | J32: 73 | K32: 9909.6207 | L32: 50.137931 | M32: 0.05 | N32: 0.983 | O32: 10.29069 | P32: 26 | Q32: 0 | R32: 0.1 | S32: 101 | T32: 0.4
E33: 2 | F33: 7.5026316 | G33: 295.12632 | H33: 12.818421 | I33: 97.894737 | J33: 75.789474 | K33: 10820.632 | L33: 49.052632 | M33: 0.046842105 | N33: 0.983 | O33: 13.104737 | P33: 22 | Q33: 0 | R33: 0.1 | S33: 86 | T33: 0.3
E34: 3 | F34: 7.3628571 | G34: 300.45 | H34: 11.795714 | I34: 54 | J34: 44.071429 | K34: 18494.929 | L34: 27 | M34: 0.02 | N34: 0.983 | O34: 15.692143 | P34: 15 | Q34: 0 | R34: 0.1 | S34: 79 | T34: 0.2
A35: 12 | B35: 4 | C35: Marian Cove | D35: MC.1.4 | E35: 1 | F35: 7.58 | G35: 278.65 | H35: na | I35: na | J35: na | K35: na | L35: na | M35: na | N35: na | O35: na | P35: 23 | Q35: na | R35: na | S35: na | T35: 0.3
E36: 2 | F36: na | G36: na | H36: 11.031481 | I36: na | J36: na | K36: na | L36: na | M36: na | N36: na | O36: na | P36: na | Q36: na | R36: na | S36: na
E37: 3 | F37: na | G37: na | H37: 10.5808 | I37: 13075.06 | J37: 42.06 | K37: 0.04 | L37: na | M37: na | N37: na | O37: na | P37: na | Q37: na | R37: na | S37: na
A38: 13 | B38: 1 | C38: Barton Peninsula | D38: BP1.1 | E38: 1 | F38: 6.9648148 | G38: 270.68889 | H38: 10.69625 | I38: 78.555556 | J38: 10860.333 | K38: 45.962963 | L38: 0.04 | M38: 0.971 | N38: 17.256667 | O38: 42 | P38: na | Q38: na | R38: na | S38: 0.4
E39: 2 | F39: 6.7216 | G39: 307.284 | H39: 11.886364 | I39: 15.24 | J39: 54919.32 | K39: 9 | L39: 0.01 | M39: 0.971 | N39: 16.9744 | O39: 40 | P39: na | Q39: na | R39: na | S39: 0.3
E40: 3 | F40: 6.5408333 | G40: 320.15833 | H40: 12.054194 | I40: 16 | J40: 54349.958 | K40: 9 | L40: 0.01 | M40: 0.971 | N40: 17.01625 | O40: 45 | P40: na | Q40: na | R40: na | S40: 0.1
...

Sheet Analisis de roca
F1: (+) Abundacia (-)
A2: Numero | B2: Nº en cronosecuencia | C2: Nombre ubicacion | D2: Codigo | E2: Rep | F2: MF1 | G2: MF2 | H2: MF3 | I2: MF4
A3: 1 | B3: 1 | C3: Bellingshausen Dome | D3: BH1.1 | E3: 1 | F3: anorthite | G3: magnetite | H3: zeolite | I3: na
E4: 2 | F4: anorthite | G4: zeolite | H4: hedenbergite | I4: na
E5: 3 | F5: na | G5: na | H5: na | I5: na
E6: 4 | F6: na | G6: na | H6: na | I6: na
A7: 2 | B7: 2 | C7: Bellingshausen Dome | D7: BH1.2 | E7: 1 | F7: anothite | G7: hedenbergite | H7: hematite | I7: na
E8: 2 | F8: quartz | G8: albite | H8: calcite | I8: na
E9: 3 | F9: na | G9: na | H9: na | I9: na
E10: 4 | F10: na | G10: na | H10: na | I10: na
A11: 3 | B11: 3 | C11: Bellingshausen Dome | D11: BH1.3 | E11: 1 | F11: anorthite | G11: zeolite | H11: hematite | I11: na
E12: 2 | F12: anorthite | G12: amphibole | H12: quartz | I12: na
E13: 3 | F13: na | G13: na | H13: na | I13: na
E14: 4 | F14: na | G14: na | H14: na | I14: na
A15: 4 | B15: 4 | C15: Bellingshausen Dome | D15: BH1.4 | E15: 1 | F15: anorthite | G15: zeolite | H15: hematite | I15: na
E16: 2 | F16: zeolite | G16: calcite | H16: phosphate | I16: hematite
E17: 3 | F17: na | G17: na | H17: na | I17: na
E18: 4 | F18: na | G18: na | H18: na | I18: na
A19: 5 | B19: 1 | C19: Bellingshausen Dome | D19: BH2.1 | E19: 1 | F19: anorthite | G19: zeolite | H19: hematite | I19: na
E20: 2 | F20: anorthite | G20: quartz | H20: na | I20: na
E21: 3 | F21: na | G21: na | H21: na | I21: na
E22: 4 | F22: na | G22: na | H22: na | I22: na
A23: 6 | B23: 2 | C23: Bellingshausen Dome | D23: BH2.2 | E23: 1 | F23: quartz | G23: anorthite | H23: zeolite | I23: hematite
E24: 2 | F24: quartz | G24: zeolite | H24: ilmenite | I24: na
E25: 3 | F25: na | G25: na | H25: na | I25: na
E26: 4 | F26: na | G26: na | H26: na | I26: na
